Workbook

Sheet Calculateur
A2: HUNTERS IMMOBILIER — CALCULATEUR DE RENTABILITÉ LOCATIVE
A3: ■ Cellules bleues = saisie manuelle ■ Cellules noires = calcul automatique ■ Résultats clés en vert
A5: 1. ACQUISITION DU BIEN | D5: A. INDICATEURS DE RENTABILITÉ
B7: Prix du bien (FAI) | C7: 124000 | E7: Rendement locatif BRUT (%) | F7: =IF(C7=0,0,C31*12/C7) -> 0.11032258
B8: Frais de notaire (calculé : 7,5 %) | C8: =C7*0.075 -> 9300 | E8: Rendement NET de charges (%) | F8: =IF(C15=0,0,(C33-C46)/C15) -> 0.066978375
B9: Montant des travaux | C9: 20000 | E9: Cashflow mensuel (hors crédit) | F9: =(C33-C46)/12 -> 955
B10: Mobilier / ameublement | C10: 10000 | E10: Effort d'épargne mensuel (avec crédit) | F10: =(C33-C46)/12-C24 -> 108.22043
B11: Honoraires Hunters — chasse ▶ barème automatique | C11: =IF(C7<=200000,7800,IF(C7<=500000,ROUND(C7*0.04,0),IF(C7<=1000000,ROUND(C7*0.03,0),ROUND(C7*0.02,0)))) -> 7800 | E11: Cashflow annuel NET (avec crédit) | F11: =(C33-C46)-C24*12 -> 1298.6451
B12: ≤ 200 000 € → forfait 7 800 € TTC (6 500 € HT) | 200 001–500 000 € → 4 % TTC | 500 001–1 000 000 € → 3 % TTC | > 1 000 000 € → 2 % TTC
B13: Autres frais d'acquisition | C13: 0 | E13: ROI annuel sur apport investi (%) | F13: =IF(C19=0,0,((C33-C46)-C24*12)/C19) -> 0.12986451
C14: =C15 -> 171100
B15: COÛT TOTAL D'ACQUISITION | C15: =C7+C8+C9+C10+C11+C12 -> 171100 | D15: B. DÉTAIL CASHFLOW ANNUEL
A17: 2. FINANCEMENT | E17: (+) Loyers encaissés (net vacance) | F17: =C33 -> 12996
C18: =C19 -> 10000 | E18: (−) Charges annuelles totales | F18: =-C46 -> -1536
B19: Apport personnel | C19: 10000 | E19: (−) Mensualités crédit (annuel) | F19: =-C24*12 -> -10161.355
B20: Montant emprunté (calculé) | C20: =MAX(0,C15-C19) -> 161100 | E20: (Assurance incluse dans mensualité ci-dessus) | F20: =0 -> 0
B21: Taux d'intérêt annuel (%) | C21: 0.035 | E21: (−) Imposition estimée (selon régime) | F21: =IF(C50=1,-MAX(0,C33*0.5*(C51+0.172)),IF(C50=2,-MAX(0,(C33-C46)*(C51+0.172)),-MAX(0,(C33-C46)*IF((C33-C46)<=42500,0.15,0.25)))) -> -3067.056
B22: Durée du crédit (ans) | C22: 25
B23: Assurance crédit (% capital / an) | C23: 0.003 | E23: = CASHFLOW NET ANNUEL (après impôts) | F23: =C33-C46-C24*12+F21 -> -1768.4109
B24: Mensualité TOTALE (crédit + assurance) | C24: =C25+C20*C23/12 -> 846.77957
B25: Mensualité crédit (hors assurance) | C25: =IF(C20<=0,0,-PMT(C21/12,C22*12,C20)) -> 806.50457 | D25: C. POINTS DE VIGILANCE
A27: 3. REVENUS LOCATIFS | E27: Taux d'endettement (HCSF ≤ 35 %) ← saisir revenus en C53 | F27: =IF(C53=0,0,C24/C53) -> 0.21169489 | G27: =IF(C53=0,"Saisir revenus",IF(F27>0.35,"⚠ >35% HCSF","✓ Conforme")) -> ✓ Conforme
E28: Ratio charges / loyer annuel brut | F28: =IF(C33=0,0,C46/C33) -> 0.11819021
B29: Loyer mensuel charges comprises | C29: 1350 | E29: Loyer min. pour cashflow nul (€/mois) | F29: =IF(C32>=1,0,(C46+C24*12)/(12*(1-C32))) -> 1026.0838
B30: Charges locatives récupérables / mois | C30: 210
B31: Loyer mensuel hors charges (calculé) | C31: =C29-C30 -> 1140 | D31: D. COMMISSIONS HUNTERS
B32: Taux de vacance locative (%) | C32: 0.05
C33: =C34*(1-C32) -> 12996 | E33: Honoraires Hunters — chasse (barème officiel auto) | F33: =C11 -> 7800
B34: Loyer annuel (net vacance) | C34: =C31*12 -> 13680 | E34: Commission mandataire N1 (55 %) | F34: =C11*0.55 -> 4290
E35: Commission mandataire N2 (60 %) | F35: =C11*0.6 -> 4680
A36: 4. CHARGES ANNUELLES
B38: Taxe foncière | C38: 900
B39: Charges de copropriété | C39: 600
B40: Assurance PNO | C40: 36
B41: Entretien / petites réparations | C41: 0
B42: Gestion locative (% loyer HC / an) | C42: 0
B43: ↳ Gestion locative (€ calculé) | C43: =C31*12*C42 -> 0
B44: Comptable / frais divers | C44: 0
C45: =C46 -> 1536
B46: TOTAL CHARGES ANNUELLES (hors crédit) | C46: =C38+C39+C40+C41+C43+C44 -> 1536
...

Sheet Projection 20 ans
A1: HUNTERS IMMOBILIER — PROJECTION SUR 20 ANS
A2: Projection indicative — paramètres extraits du calculateur ◆ Revalorisation loyer : +1 %/an ◆ Revalorisation bien : +2 %/an
B3: Revalorisation loyer / an (%) | C3: 0.01
B4: Revalorisation bien / an (%) | C4: 0.02
B6: An | C6: Loyer annuel (net vacance) | D6: Charges annuelles | E6: Mensualités crédit ann. | F6: Cashflow avant IS | G6: Valeur du bien | H6: Capital remb. cumulé | I6: Plus-value latente | J6: Rendement brut % | K6: TRI simulé (%) | L6: Capital restant dû | M6: Richesse nette
B7: An 1 | C7: =Calculateur!C33 -> 12996 | D7: =Calculateur!C45 -> 1536 | E7: =(Calculateur!C24+Calculateur!C19*Calculateur!C22/12)*12 -> 260161.35 | F7: =C7-D7-E7 -> -248701.35 | G7: =Calculateur!C7*(1+C4) -> 126480 | H7: =IF(Calculateur!C20<=0,0,-CUMPRINC(Calculateur!C21/12,Calculateur!C22*12,Calculateur!C20,1,MIN(12,Calculateur!C22*12),0)) -> 4104.9902 | I7: =G7-Calculateur!C7 -> 2480 | J7: =IF(G7=0,0,C7/G7) -> 0.10275142 | L7: =MAX(0,Calculateur!C20-H7) -> 156995.01 | M7: =G7-L7 -> -30515.01
B8: An 2 | C8: =C7*(1+C3) -> 13125.96 | D8: =Calculateur!C45 -> 1536 | E8: =(Calculateur!C24+Calculateur!C19*Calculateur!C22/12)*12 -> 260161.35 | F8: =C8-D8-E8 -> -248571.39 | G8: =G7*(1+C4) -> 129009.6 | H8: =IF(Calculateur!C20<=0,0,-CUMPRINC(Calculateur!C21/12,Calculateur!C22*12,Calculateur!C20,1,MIN(24,Calculateur!C22*12),0)) -> 8355.9824 | I8: =G8-Calculateur!C7 -> 5009.6 | J8: =IF(G8=0,0,C8/G8) -> 0.10174406 | L8: =MAX(0,Calculateur!C20-H8) -> 152744.02 | M8: =G8-L8 -> -23734.418
B9: An 3 | C9: =C8*(1+C3) -> 13257.22 | D9: =Calculateur!C45 -> 1536 | E9: =(Calculateur!C24+Calculateur!C19*Calculateur!C22/12)*12 -> 260161.35 | F9: =C9-D9-E9 -> -248440.14 | G9: =G8*(1+C4) -> 131589.79 | H9: =IF(Calculateur!C20<=0,0,-CUMPRINC(Calculateur!C21/12,Calculateur!C22*12,Calculateur!C20,1,MIN(36,Calculateur!C22*12),0)) -> 12758.169 | I9: =G9-Calculateur!C7 -> 7589.792 | J9: =IF(G9=0,0,C9/G9) -> 0.10074657 | L9: =MAX(0,Calculateur!C20-H9) -> 148341.83 | M9: =G9-L9 -> -16752.039
B10: An 4 | C10: =C9*(1+C3) -> 13389.792 | D10: =Calculateur!C45 -> 1536 | E10: =(Calculateur!C24+Calculateur!C19*Calculateur!C22/12)*12 -> 260161.35 | F10: =C10-D10-E10 -> -248307.56 | G10: =G9*(1+C4) -> 134221.59 | H10: =IF(Calculateur!C20<=0,0,-CUMPRINC(Calculateur!C21/12,Calculateur!C22*12,Calculateur!C20,1,MIN(48,Calculateur!C22*12),0)) -> 17316.929 | I10: =G10-Calculateur!C7 -> 10221.588 | J10: =IF(G10=0,0,C10/G10) -> 0.099758854 | L10: =MAX(0,Calculateur!C20-H10) -> 143783.07 | M10: =G10-L10 -> -9561.4832
B11: An 5 | C11: =C10*(1+C3) -> 13523.69 | D11: =Calculateur!C45 -> 1536 | E11: =(Calculateur!C24+Calculateur!C19*Calculateur!C22/12)*12 -> 260161.35 | F11: =C11-D11-E11 -> -248173.67 | G11: =G10*(1+C4) -> 136906.02 | H11: =IF(Calculateur!C20<=0,0,-CUMPRINC(Calculateur!C21/12,Calculateur!C22*12,Calculateur!C20,1,MIN(60,Calculateur!C22*12),0)) -> 22037.83 | I11: =G11-Calculateur!C7 -> 12906.02 | J11: =IF(G11=0,0,C11/G11) -> 0.098780826 | L11: =MAX(0,Calculateur!C20-H11) -> 139062.17 | M11: =G11-L11 -> -2156.1509
B12: An 6 | C12: =C11*(1+C3) -> 13658.927 | D12: =Calculateur!C45 -> 1536 | E12: =(Calculateur!C24+Calculateur!C19*Calculateur!C22/12)*12 -> 260161.35 | F12: =C12-D12-E12 -> -248038.43 | G12: =G11*(1+C4) -> 139644.14 | H12: =IF(Calculateur!C20<=0,0,-CUMPRINC(Calculateur!C21/12,Calculateur!C22*12,Calculateur!C20,1,MIN(72,Calculateur!C22*12),0)) -> 26926.638 | I12: =G12-Calculateur!C7 -> 15644.14 | J12: =IF(G12=0,0,C12/G12) -> 0.097812387 | L12: =MAX(0,Calculateur!C20-H12) -> 134173.36 | M12: =G12-L12 -> 5470.7782
B13: An 7 | C13: =C12*(1+C3) -> 13795.516 | D13: =Calculateur!C45 -> 1536 | E13: =(Calculateur!C24+Calculateur!C19*Calculateur!C22/12)*12 -> 260161.35 | F13: =C13-D13-E13 -> -247901.84 | G13: =G12*(1+C4) -> 142437.02 | H13: =IF(Calculateur!C20<=0,0,-CUMPRINC(Calculateur!C21/12,Calculateur!C22*12,Calculateur!C20,1,MIN(84,Calculateur!C22*12),0)) -> 31989.327 | I13: =G13-Calculateur!C7 -> 18437.023 | J13: =IF(G13=0,0,C13/G13) -> 0.096853442 | L13: =MAX(0,Calculateur!C20-H13) -> 129110.67 | M13: =G13-L13 -> 13326.35
B14: An 8 | C14: =C13*(1+C3) -> 13933.471 | D14: =Calculateur!C45 -> 1536 | E14: =(Calculateur!C24+Calculateur!C19*Calculateur!C22/12)*12 -> 260161.35 | F14: =C14-D14-E14 -> -247763.88 | G14: =G13*(1+C4) -> 145285.76 | H14: =IF(Calculateur!C20<=0,0,-CUMPRINC(Calculateur!C21/12,Calculateur!C22*12,Calculateur!C20,1,MIN(96,Calculateur!C22*12),0)) -> 37232.08 | I14: =G14-Calculateur!C7 -> 21285.763 | J14: =IF(G14=0,0,C14/G14) -> 0.095903898 | L14: =MAX(0,Calculateur!C20-H14) -> 123867.92 | M14: =G14-L14 -> 21417.843
B15: An 9 | C15: =C14*(1+C3) -> 14072.806 | D15: =Calculateur!C45 -> 1536 | E15: =(Calculateur!C24+Calculateur!C19*Calculateur!C22/12)*12 -> 260161.35 | F15: =C15-D15-E15 -> -247624.55 | G15: =G14*(1+C4) -> 148191.48 | H15: =IF(Calculateur!C20<=0,0,-CUMPRINC(Calculateur!C21/12,Calculateur!C22*12,Calculateur!C20,1,MIN(108,Calculateur!C22*12),0)) -> 42661.302 | I15: =G15-Calculateur!C7 -> 24191.479 | J15: =IF(G15=0,0,C15/G15) -> 0.094963664 | L15: =MAX(0,Calculateur!C20-H15) -> 118438.7 | M15: =G15-L15 -> 29752.78
B16: An 10 | C16: =C15*(1+C3) -> 14213.534 | D16: =Calculateur!C45 -> 1536 | E16: =(Calculateur!C24+Calculateur!C19*Calculateur!C22/12)*12 -> 260161.35 | F16: =C16-D16-E16 -> -247483.82 | G16: =G15*(1+C4) -> 151155.31 | H16: =IF(Calculateur!C20<=0,0,-CUMPRINC(Calculateur!C21/12,Calculateur!C22*12,Calculateur!C20,1,MIN(120,Calculateur!C22*12),0)) -> 48283.625 | I16: =G16-Calculateur!C7 -> 27155.308 | J16: =IF(G16=0,0,C16/G16) -> 0.094032648 | L16: =MAX(0,Calculateur!C20-H16) -> 112816.38 | M16: =G16-L16 -> 38338.933
B17: An 11 | C17: =C16*(1+C3) -> 14355.669 | D17: =Calculateur!C45 -> 1536 | E17: =(Calculateur!C24+Calculateur!C19*Calculateur!C22/12)*12 -> 260161.35 | F17: =C17-D17-E17 -> -247341.69 | G17: =G16*(1+C4) -> 154178.41 | H17: =IF(Calculateur!C20<=0,0,-CUMPRINC(Calculateur!C21/12,Calculateur!C22*12,Calculateur!C20,1,MIN(132,Calculateur!C22*12),0)) -> 54105.916 | I17: =G17-Calculateur!C7 -> 30178.414 | J17: =IF(G17=0,0,C17/G17) -> 0.093110759 | L17: =MAX(0,Calculateur!C20-H17) -> 106994.08 | M17: =G17-L17 -> 47184.33
B18: An 12 | C18: =C17*(1+C3) -> 14499.226 | D18: =Calculateur!C45 -> 1536 | E18: =(Calculateur!C24+Calculateur!C19*Calculateur!C22/12)*12 -> 260161.35 | F18: =C18-D18-E18 -> -247198.13 | G18: =G17*(1+C4) -> 157261.98 | H18: =IF(Calculateur!C20<=0,0,-CUMPRINC(Calculateur!C21/12,Calculateur!C22*12,Calculateur!C20,1,MIN(144,Calculateur!C22*12),0)) -> 60135.289 | I18: =G18-Calculateur!C7 -> 33261.983 | J18: =IF(G18=0,0,C18/G18) -> 0.092197908 | L18: =MAX(0,Calculateur!C20-H18) -> 100964.71 | M18: =G18-L18 -> 56297.272
B19: An 13 | C19: =C18*(1+C3) -> 14644.218 | D19: =Calculateur!C45 -> 1536 | E19: =(Calculateur!C24+Calculateur!C19*Calculateur!C22/12)*12 -> 260161.35 | F19: =C19-D19-E19 -> -247053.14 | G19: =G18*(1+C4) -> 160407.22 | H19: =IF(Calculateur!C20<=0,0,-CUMPRINC(Calculateur!C21/12,Calculateur!C22*12,Calculateur!C20,1,MIN(156,Calculateur!C22*12),0)) -> 66379.108 | I19: =G19-Calculateur!C7 -> 36407.222 | J19: =IF(G19=0,0,C19/G19) -> 0.091294007 | L19: =MAX(0,Calculateur!C20-H19) -> 94720.892 | M19: =G19-L19 -> 65686.33
B20: An 14 | C20: =C19*(1+C3) -> 14790.66 | D20: =Calculateur!C45 -> 1536 | E20: =(Calculateur!C24+Calculateur!C19*Calculateur!C22/12)*12 -> 260161.35 | F20: =C20-D20-E20 -> -246906.69 | G20: =G19*(1+C4) -> 163615.37 | H20: =IF(Calculateur!C20<=0,0,-CUMPRINC(Calculateur!C21/12,Calculateur!C22*12,Calculateur!C20,1,MIN(168,Calculateur!C22*12),0)) -> 72845.001 | I20: =G20-Calculateur!C7 -> 39615.367 | J20: =IF(G20=0,0,C20/G20) -> 0.090398968 | L20: =MAX(0,Calculateur!C20-H20) -> 88254.999 | M20: =G20-L20 -> 75360.368
B21: An 15 | C21: =C20*(1+C3) -> 14938.567 | D21: =Calculateur!C45 -> 1536 | E21: =(Calculateur!C24+Calculateur!C19*Calculateur!C22/12)*12 -> 260161.35 | F21: =C21-D21-E21 -> -246758.79 | G21: =G20*(1+C4) -> 166887.67 | H21: =IF(Calculateur!C20<=0,0,-CUMPRINC(Calculateur!C21/12,Calculateur!C22*12,Calculateur!C20,1,MIN(180,Calculateur!C22*12),0)) -> 79540.866 | I21: =G21-Calculateur!C7 -> 42887.674 | J21: =IF(G21=0,0,C21/G21) -> 0.089512703 | L21: =MAX(0,Calculateur!C20-H21) -> 81559.134 | M21: =G21-L21 -> 85328.54
B22: An 16 | C22: =C21*(1+C3) -> 15087.953 | D22: =Calculateur!C45 -> 1536 | E22: =(Calculateur!C24+Calculateur!C19*Calculateur!C22/12)*12 -> 260161.35 | F22: =C22-D22-E22 -> -246609.4 | G22: =G21*(1+C4) -> 170225.43 | H22: =IF(Calculateur!C20<=0,0,-CUMPRINC(Calculateur!C21/12,Calculateur!C22*12,Calculateur!C20,1,MIN(192,Calculateur!C22*12),0)) -> 86474.882 | I22: =G22-Calculateur!C7 -> 46225.427 | J22: =IF(G22=0,0,C22/G22) -> 0.088635128 | L22: =MAX(0,Calculateur!C20-H22) -> 74625.118 | M22: =G22-L22 -> 95600.31
B23: An 17 | C23: =C22*(1+C3) -> 15238.832 | D23: =Calculateur!C45 -> 1536 | E23: =(Calculateur!C24+Calculateur!C19*Calculateur!C22/12)*12 -> 260161.35 | F23: =C23-D23-E23 -> -246458.52 | G23: =G22*(1+C4) -> 173629.94 | H23: =IF(Calculateur!C20<=0,0,-CUMPRINC(Calculateur!C21/12,Calculateur!C22*12,Calculateur!C20,1,MIN(204,Calculateur!C22*12),0)) -> 93655.521 | I23: =G23-Calculateur!C7 -> 49629.936 | J23: =IF(G23=0,0,C23/G23) -> 0.087766156 | L23: =MAX(0,Calculateur!C20-H23) -> 67444.479 | M23: =G23-L23 -> 106185.46
B24: An 18 | C24: =C23*(1+C3) -> 15391.22 | D24: =Calculateur!C45 -> 1536 | E24: =(Calculateur!C24+Calculateur!C19*Calculateur!C22/12)*12 -> 260161.35 | F24: =C24-D24-E24 -> -246306.13 | G24: =G23*(1+C4) -> 177102.53 | H24: =IF(Calculateur!C20<=0,0,-CUMPRINC(Calculateur!C21/12,Calculateur!C22*12,Calculateur!C20,1,MIN(216,Calculateur!C22*12),0)) -> 101091.55 | I24: =G24-Calculateur!C7 -> 53102.535 | J24: =IF(G24=0,0,C24/G24) -> 0.086905704 | L24: =MAX(0,Calculateur!C20-H24) -> 60008.448 | M24: =G24-L24 -> 117094.09
B25: An 19 | C25: =C24*(1+C3) -> 15545.133 | D25: =Calculateur!C45 -> 1536 | E25: =(Calculateur!C24+Calculateur!C19*Calculateur!C22/12)*12 -> 260161.35 | F25: =C25-D25-E25 -> -246152.22 | G25: =G24*(1+C4) -> 180644.59 | H25: =IF(Calculateur!C20<=0,0,-CUMPRINC(Calculateur!C21/12,Calculateur!C22*12,Calculateur!C20,1,MIN(228,Calculateur!C22*12),0)) -> 108792.06 | I25: =G25-Calculateur!C7 -> 56644.585 | J25: =IF(G25=0,0,C25/G25) -> 0.086053687 | L25: =MAX(0,Calculateur!C20-H25) -> 52307.939 | M25: =G25-L25 -> 128336.65
B26: An 20 | C26: =C25*(1+C3) -> 15700.584 | D26: =Calculateur!C45 -> 1536 | E26: =(Calculateur!C24+Calculateur!C19*Calculateur!C22/12)*12 -> 260161.35 | F26: =C26-D26-E26 -> -245996.77 | G26: =G25*(1+C4) -> 184257.48 | H26: =IF(Calculateur!C20<=0,0,-CUMPRINC(Calculateur!C21/12,Calculateur!C22*12,Calculateur!C20,1,MIN(240,Calculateur!C22*12),0)) -> 116766.45 | I26: =G26-Calculateur!C7 -> 60257.477 | J26: =IF(G26=0,0,C26/G26) -> 0.085210023 | L26: =MAX(0,Calculateur!C20-H26) -> 44333.547 | M26: =G26-L26 -> 139923.93
B27: TOTAL / AN 20 | C27: =SUM(C7:C26) -> 286158.98 | D27: =SUM(D7:D26) -> 30720 | E27: =SUM(E7:E26) -> 5203227.1 | F27: =SUM(F7:F26) -> -4947788.1 | G27: =G26 -> 184257.48 | H27: =H26 -> 116766.45 | I27: =I26 -> 60257.477 | J27: =J26 -> 0.085210023
A28: VAN (actualisation 5 %) | F28: =NPV(0.05,F7:F26) -> -3085841.5
A29: TRI (Taux de Rendement Interne) | F29: =IFERROR(IRR(F7:F26),0) -> 0
A31: SIMULATION REVENTE (Plus-value nette après impôt)
B32: Durée détention simulée (ans) | C32: 10
B33: Valeur de revente estimée (€) | C33: =Calculateur!C7*(1+C4)^C32 -> 151155.31
B34: Capital restant dû à la revente (€) | C34: =MAX(0,Calculateur!C20-(-CUMPRINC(Calculateur!C21/12,Calculateur!C22*12,Calculateur!C20,1,MIN(C32*12,Calculateur!C22*12),0))) -> 112816.38
B35: Plus-value brute (€) | C35: =MAX(0,C33-Calculateur!C7) -> 27155.308
B36: Abattement IR durée détention (%) | C36: =IF(C32<6,0,IF(C32>=22,1,MIN(1,(C32-5)*0.06))) -> 0.3
B37: Abattement PS durée détention (%) | C37: =IF(C32<6,0,IF(C32>=30,1,IF(C32<=21,(C32-5)*0.0165,MIN(1,0.264+(C32-21)*0.09)))) -> 0.0825
B38: Impôt PV IR (19% après abattement) | C38: =MAX(0,C35*(1-C36)*0.19) -> 3611.656
B39: Prélèvements sociaux PV (17.2% après abattement) | C39: =MAX(0,C35*(1-C37)*0.172) -> 4285.3792
B40: PLUS-VALUE NETTE APRÈS IMPÔT (€) | C40: =C35-C38-C39 -> 19258.273
B41: Produit NET de cession (€) (après remboursement crédit) | C41: =C33-C34-C38-C39 -> 30441.898

Sheet Comparaison scenarios
A1: HUNTERS IMMOBILIER — COMPARAISON 3 SCÉNARIOS
A2: Saisissez les paramètres de chaque scénario — comparaison côte à côte pour arbitrage client
B4: Paramètre | C4: Scénario A | D4: Scénario B | E4: Scénario C
B5: Prix du bien FAI | C5: 150000 | D5: 185000 | E5: 250000
B6: Loyer mensuel HC | C6: 650 | D6: 800 | E6: 1100
B7: Travaux | C7: 0 | D7: 15000 | E7: 35000
B8: Honoraires Hunters | C8: 7800 | D8: 7800 | E8: 9980
B9: Frais de notaire | C9: 11250 | D9: 13875 | E9: 18750
B10: Apport | C10: 20000 | D10: 25000 | E10: 40000
B11: Durée crédit (ans) | C11: 20 | D11: 20 | E11: 25
B12: Taux crédit (%) | C12: 0.034 | D12: 0.035 | E12: 0.036
B13: Taux de vacance (%) | C13: 0.05 | D13: 0.05 | E13: 0.08
B14: Charges annuelles totales | C14: 1500 | D14: 1980 | E14: 2800
A16: RÉSULTATS CALCULÉS
B18: Coût total acquisition | C18: =C5+C7+C8+C9 -> 169050 | D18: =D5+D7+D8+D9 -> 221675 | E18: =E5+E7+E8+E9 -> 313730
B19: Loyer annuel net vacance | C19: =C6*12*(1-C13) -> 7410 | D19: =D6*12*(1-D13) -> 9120 | E19: =E6*12*(1-E13) -> 12144
B20: Rendement brut (%) | C20: =IF(C5=0,0,C6*12/C5) -> 0.052 | D20: =IF(D5=0,0,D6*12/D5) -> 0.051891892 | E20: =IF(E5=0,0,E6*12/E5) -> 0.0528
B21: Rendement net charges (%) | C21: =IF(C5=0,0,(C6*12*(1-C13)-C14)/C5) -> 0.0394 | D21: =IF(D5=0,0,(D6*12*(1-D13)-D14)/D5) -> 0.038594595 | E21: =IF(E5=0,0,(E6*12*(1-E13)-E14)/E5) -> 0.037376
B22: Mensualité crédit (€/mois) | C22: =IF(C18-C10<=0,0,-PMT(C12/12,C11*12,C18-C10)) -> 856.79054 | D22: =IF(D18-D10<=0,0,-PMT(D12/12,D11*12,D18-D10)) -> 1140.6358 | E22: =IF(E18-E10<=0,0,-PMT(E12/12,E11*12,E18-E10)) -> 1385.0812
B23: Cashflow mensuel avec crédit | C23: =(C6*12*(1-C13)-C14)/12-C22 -> -364.29054 | D23: =(D6*12*(1-D13)-D14)/12-D22 -> -545.63578 | E23: =(E6*12*(1-E13)-E14)/12-E22 -> -606.41456
B24: Cashflow annuel (avec crédit) | C24: =C23*12 -> -4371.4865 | D24: =D23*12 -> -6547.6293 | E24: =E23*12 -> -7276.9747
A25: ✍ Recommandation : ____________________________________________________________________________________________________________ | B25: ROI annuel sur apport (%) | C25: =IF(C10=0,0,C24/C10) -> -0.21857433 | D25: =IF(D10=0,0,D24/D10) -> -0.26190517 | E25: =IF(E10=0,0,E24/E10) -> -0.18192437
B26: Taux d'endettement (revenu 4 000€/mois) | C26: =IF(C22=0,0,C22/4000) -> 0.21419764 | D26: =IF(D22=0,0,D22/4000) -> 0.28515894 | E26: =IF(E22=0,0,E22/4000) -> 0.34627031
B27: Alerte HCSF (≤ 35%) | C27: =IF(C26>0.35,"⚠ >35% HCSF","✓ Conforme") -> ✓ Conforme | D27: =IF(D26>0.35,"⚠ >35% HCSF","✓ Conforme") -> ✓ Conforme | E27: =IF(E26>0.35,"⚠ >35% HCSF","✓ Conforme") -> ✓ Conforme
B28: → Meilleur cashflow annuel | C28: =IF(AND(C24>=D24,C24>=E24),"★ MEILLEUR","—") -> ★ MEILLEUR | D28: =IF(AND(D24>=C24,D24>=E24),"★ MEILLEUR","—") -> — | E28: =IF(AND(E24>=C24,E24>=D24),"★ MEILLEUR","—") -> —

Sheet Lexique
A1: HUNTERS IMMOBILIER — LEXIQUE & MÉTHODE DE CALCUL
A2: Définitions des indicateurs utilisés dans le calculateur — à partager avec le client si utile
B4: Rendement brut | C4: Loyer annuel HORS CHARGES / Prix FAI × 100. Toujours calculé sur loyer HC (hors charges locatives). Ne tient pas compte des charges ni de la fiscalité. Indicateur de comparaison rapide entre biens.
B5: Rendement net de charges | C5: (Loyers annuels nets vacance − Charges annuelles) / Prix total acquisition × 100. Indicateur fiable pour comparer des biens entre eux.
B6: Cashflow | C6: Flux net mensuel ou annuel après déduction de toutes les charges et des mensualités de crédit. Positif = bien autofinancé. Négatif = effort d'épargne du propriétaire.
B7: Effort d'épargne | C7: Montant mensuel que l'investisseur doit apporter de sa poche pour équilibrer le bien. Cashflow négatif = effort d'épargne. Objectif : le minimiser ou l'annuler.
B8: Taux de vacance | C8: % du temps annuel où le bien est inoccupé. Hypothèse prudente : 5 % (Tours centre, meublé), 8 % (périphérie, travaux, saisonnier).
B9: LMNP — Loueur Meublé Non Pro | C9: Régime fiscal permettant l'amortissement comptable du bien. Réduit la base imposable, parfois à zéro sur 20–30 ans. Loyer meublé > loyer nu de 10–15 % à surface égale.
B10: Déficit foncier (location nue) | C10: Revenus fonciers nets négatifs (charges > loyers) = déficit imputable sur revenu global jusqu'à 10 700 €/an. Puissant en présence de travaux importants.
B11: SCI à l'IS | C11: Société Civile Immobilière imposée à l'IS. Amortissements possibles, IS à 15 % (jusqu'à 42 500 €) puis 25 %. Adapté aux patrimoines importants ou TMI élevés.
B12: TMI — Tranche Marginale d'Imposition | C12: Taux d'imposition de la dernière tranche de revenu. France 2026 : 0 %, 11 %, 30 %, 41 %, 45 %. Détermine le coût fiscal de la location nue.
B13: Plus-value latente | C13: Différence entre valeur actuelle estimée du bien et son prix d'achat. Non réalisée tant que le bien n'est pas vendu. Croît avec l'hypothèse de revalorisation (+2 %/an dans la projection).
B14: Capital remboursé cumulé | C14: Cumul des remboursements de capital depuis l'origine du crédit (hors intérêts). Représente de l'épargne forcée — souvent sous-estimé par les investisseurs débutants.
B15: ROI sur apport | C15: Retour sur investissement annuel ramené à l'apport injecté. Mesure l'effet de levier du crédit immobilier. Un ROI de 15 % signifie que l'apport est récupéré en ~7 ans.
... B19: VAN — Valeur Actuelle Nette | C19: Somme des cashflows futurs actualisés à 5%. VAN > 0 = l'investissement crée de la valeur. Permet de comparer des investissements de montants et durées différents.
A20: Frais de notaire | B20: Ancien : ~7,5% du prix FAI | Neuf/VEFA : ~2,5%. Comprennent droits de mutation, émoluments, débours. Généralement non financés par la banque.
A21: HUNTERS IMMOBILIER — Calculateur de Rentabilité v2.0 / 2026 — Confidentiel — © Hunters Immobilier
